Workbook
Name clientesfantasia: Alan!$K$9:$K$34
Name clientesfantasia: Bernardo!$K$9:$K$34
Name clientesfantasia: 'Cópia de Cópia de BDHorárioeBen'!$D$17
Name clientesfantasia: 'Planilha simplificada'!$D$7:$D$32
Name clientesfantasia: 'sapucaia novo'!$C$3:$C$16
Name clientesfantasia: #REF!
Name IntervaloNomeadoteste: #REF!

Sheet Cliente IA
A1: codigo_cliente | B1: razao_social | C1: cnpj | D1: nome_responsavel | E1: telefone_responsavel | F1: cep | G1: logradouro | H1: numero | I1: complemento | J1: bairro | K1: cidade | L1: uf | M1: gestor_operacional | N1: Posto do Gestor | O1: periodicidade_visita | P1: ranking_prioridades | Q1: escopo_trabalho
A2: FC001 | B2: ALFA SERRANA | C2: 28.462.927/0001-62 | D2: Gabriela | E2: 24 98802-3530 | F2: 25625-140 | G2: Rua Professor Pinto Ferreira | H2: 36 | J2: Centro | K2: Petrópolis | L2: RJ | M2: Brenda | N2: Coordenador ADM | O2: Bimestral | P2: C04 | Q2: 3151.66
A3: FC003 | B3: ANAPOLY - CONDOMINIO | C3: 17.901.124/0001-40 | D3: Antonio | E3: 24 98881-6144 | F3: 25710-180 | G3: Rua Hyvio Naliato | H3: 786 | I3: — | J3: Cascatinha | K3: Petrópolis | L3: RJ | M3: Wiliam | N3: Supervisor 02 | O3: Sob Demanda | P3: C13 | Q3: 1262.47
A4: FC004 | B4: ARMAZENS RENATO | C4: 31.121.320/0001-23 | D4: Gerson Renato Sutter | E4: 24 99832-5321 | F4: 25625-022 | G4: Rua Teresa | H4: 1566 | I4: SL 202 | J4: Alto da Serra | K4: Petrópolis | L4: RJ | M4: Bernardo | N4: Supervisor 01 | O4: Mensal | P4: B06 | Q4: 7623.01
A5: FC008 | B5: BRAL- MAX | C5: 01.399.482/0001-67 | D5: Roberta | E5: 24 99911-7347 | F5: 25630-021 | G5: Avenida General Marciano Magalhães | H5: 61 | I5: — | J5: Morin | K5: Petrópolis | L5: RJ | M5: Bernardo | N5: Supervisor 01 | O5: Mensal | P5: B01 | Q5: 15382.41
A6: FC009a | B6: C. CORREAS - ABC | C6: 31.161.235/0013-22 | D6: Alex | E6: 24 98809-0492 | F6: 25625-026 | G6: Rua Teresa | H6: 1515 | I6: 203 | J6: Alto da Serra | K6: Petrópolis | L6: RJ | M6: Bernardo | N6: Supervisor 01 | O6: Mensal | P6: A01 | Q6: 1892.48
A7: FC009b | B7: C. CORREAS - BAUHAUS | C7: 31.161.235/0002-70 | D7: Alex | E7: 24 98809-0492 | F7: 25680-199 | G7: Rua Nelson de Sá Earp | H7: 95 | I7: Sobreloja | J7: Centro | K7: Petrópolis | L7: RJ | M7: Bernardo | N7: Supervisor 01 | O7: Quinzenal | P7: A01 | Q7: 4442.71
A8: FC009c | B8: C. CORREAS - CASCATINHA | C8: 31.161.235/0012-41 | D8: Alex | E8: 24 98809-0492 | F8: 25655-320 | G8: Rua Hyvio Natalino | H8: 110 | I8: — | J8: Cascatinha | K8: Petrópolis | L8: RJ | M8: Bernardo | N8: Supervisor 01 | O8: Mensal | P8: A01 | Q8: 2182.29
A9: FC009d | B9: C. CORREAS - ITAIPAVA | C9: 31.161.235/0011-60 | D9: Alex | E9: 24 98809-0492 | F9: 25750-226 | G9: Estrada União e Indústria | H9: 10126 | I9: — | J9: Itaipava | K9: Petrópolis | L9: RJ | M9: Bernardo | N9: Supervisor 01 | O9: Quinzenal | P9: A01 | Q9: 3358.65
A10: FC009e | B10: C. CORREAS - MATRIZ | C10: 04.237.600/0001-29 | D10: Alex | E10: 24 98809-0492 | F10: 25730-040 | G10: Rua Rodolfo Figueira de Melo | H10: 17 | I10: — | J10: Correias | K10: Petrópolis | L10: RJ | M10: Bernardo | N10: Supervisor 01 | O10: Quinzenal | P10: A01 | Q10: 9347.07
A11: FC009f | B11: C. CORREAS - N. IGUAÇU GV | C11: 30.808.497/0006-44 | D11: Alex | E11: 24 98809-0492 | F11: 26210-170 | G11: Rua Getúlio Vargas | H11: 109 | I11: — | J11: Centro | K11: Nova Iguaçu | L11: RJ | M11: Bernardo | N11: Supervisor 01 | O11: Mensal | P11: A01 | Q11: 3825.6
A12: FC009g | B12: C. CORREAS - N. IGUAÇU OT | C12: 30.808.497/0001-30 | D12: Alex | E12: 24 98809-0492 | F12: 26210-200 | G12: Rua Otávio Tarquino | H12: 74 | I12: — | J12: Centro | K12: Nova Iguaçu | L12: RJ | M12: Bernardo | N12: Supervisor 01 | O12: Mensal | P12: A01 | Q12: 4875.14
A13: FC009h | B13: C. CORREAS - N. FRIBURGO COLETA | C13: 68.665.868/0001-44 | D13: Alex | E13: 24 98809-0492 | F13: 28625-340 | G13: Praça 1º de Maio | H13: 8 | I13: — | J13: Olaria | K13: Nova Friburgo | L13: RJ | M13: Bernardo | N13: Supervisor 01 | O13: Mensal | P13: A01 | Q13: 2551.21
A14: FC009i | B14: C. CORREAS - N. FRIBURGO MATRIZ | C14: 31.161.235/0001-99 | D14: Alex | E14: 24 98809-0492 | F14: 28613-050 | G14: Travessa São João | H14: 8 | I14: — | J14: Centro | K14: Nova Friburgo | L14: RJ | M14: Bernardo | N14: Supervisor 01 | O14: Mensal | P14: A01 | Q14: 3825.6
A15: FC009j | B15: C. CORREAS - BAUHAUS KIDS | C15: 31.161.235/0002-70 | D15: Alex | E15: 24 98809-0492 | F15: 25680-199 | G15: Rua Nelson de Sá Earp | H15: 95 | I15: Sobreloja | J15: Centro | K15: Petrópolis | L15: RJ | M15: Bernardo | N15: Supervisor 01 | O15: Quinzenal | P15: A01 | Q15: 4442.71
A16: FC009k | B16: C. CORREAS - SJVRP | C16: 31.161.235/0010-80 | D16: Alex | E16: 24 98809-0492 | F16: 25865-000 | G16: Praça João Werneck | H16: 55 | I16: — | J16: Centro | K16: São José do Vale do Rio Preto | L16: RJ | M16: Bernardo | N16: Supervisor 01 | O16: Mensal | P16: A01 | Q16: 3290.87
A17: FC009l | B17: C. CORREAS - SUS | C17: 31.161.235/0009-46 | D17: Alex | E17: 24 98809-0492 | F17: 25655-010 | G17: Rua Castro Alves | H17: 67 | I17: — | J17: Correias | K17: Petrópolis | L17: RJ | M17: Bernardo | N17: Supervisor 01 | O17: Quinzenal | P17: A01 | Q17: 2783.86
A18: FC009m | B18: C. CORREAS - TERESOPOLIS | C18: 31.161.235/0014-03 | D18: Alex | E18: 24 98809-0492 | F18: 25953-160 | G18: Praça Baltazar da Silveira | H18: 92 | I18: Loja | J18: Várzea | K18: Teresópolis | L18: RJ | M18: Bernardo | N18: Supervisor 01 | O18: Mensal | P18: A01 | Q18: 3825.6
... A29: FC014 | B29: CORREAS MALL | C29: 48.399.206/0001-62 | D29: Renata Senna | E29: 24 2242-2003 | F29: 25720-071 | G29: Estrada União e Indústria | H29: 5077 | I29: — | J29: Corrêas | K29: Petrópolis | L29: RJ | M29: Wiliam | N29: Supervisor 02 | O29: Mensal | P29: C01 | Q29: 3443.28
A30: FC016 | B30: DIAS DE OLIVEIRA - CONDOMINIO | C30: 09.604.970/0001-70 | D30: Jose Almiro | E30: 24 98813-6418 | F30: 25665-140 | G30: Rua Sebastião Heinen | H30: 33 | J30: Duarte Silveira | K30: Petrópolis | L30: RJ | M30: Brenda | N30: Coordenador ADM | O30: Sob Demanda | P30: C07 | Q30: 1998.25
A31: FC017 | B31: DONA GUILHERMINA - CONDOMINIO | C31: SEM CONTRATO | D31: Telma | E31: 24 98818-2877 | F31: 25750-226 | G31: Estrada União e Indústria | H31: 12104 | I31: — | J31: Itaipava | K31: Petrópolis | L31: RJ | M31: Wiliam | N31: Supervisor 02 | O31: Quinzenal | P31: C09 | Q31: 1926.07
A32: FC018 | B32: ESCRITORIO DO JOÃO | C32: SEM CONTRATO | D32: Leonardo Sutter | E32: 24 2231-6910 | F32: 25680-176 | G32: Rua Professor Stroeler | H32: 428 | I32: Sala 303 | J32: Quarteirão Brasileiro | K32: Petrópolis | L32: RJ | M32: Brenda | N32: Coordenador ADM | O32: Sob Demanda | P32: C26 | Q32: 0
A33: FC020 | B33: FUNERÁRIA OSWALDO CRUZ | C33: 29.671.468/0001-90 | D33: Renan | E33: 24 98807-7716 | F33: 25610-140 | G33: Praça Oswaldo Cruz | H33: 36 e 40 | I33: — | J33: Centro | K33: Petrópolis | L33: RJ | M33: Wiliam | N33: Supervisor 02 | O33: Quinzenal | P33: B09 | Q33: 4435.34
A34: FC022 | B34: GIÓIA - CONDOMINIO | C34: 36.551.208/0001-46 | D34: Sueli | E34: 24 98808-3861 | F34: 25660-003 | G34: Rua Bingen | H34: 684 | J34: Bingen | K34: Petrópolis | L34: RJ | M34: Brenda | N34: Coordenador ADM | O34: Sob Demanda | P34: C17 | Q34: 748.26
A35: FC023 | B35: GREEN OFFICES - CONDOMINIO | C35: 28.466.072/0001-48 | D35: Ualace | E35: 24 99309-8811 | F35: 25680-176 | G35: Rua Professor Stroeler | H35: 428 | I35: — | J35: Quarteirão Brasileiro | K35: Petrópolis | L35: RJ | M35: Bernardo | N35: Supervisor 01 | O35: Semanal | P35: A04 | Q35: 27970.65
A36: FC024 | B36: HGL ENGENHARIA LTDA | C36: 31.276.026/0001-90 | D36: Daniele Haubrich | E36: 24 99946-7010 | F36: 25665-453 | G36: Rua Doutor Arthur Cruz | H36: 300 | I36: — | J36: Duarte Silveira | K36: Petrópolis | L36: RJ | M36: Wiliam | N36: Supervisor 02 | O36: Bimestral | P36: C02 | Q36: 3269.41
A37: FC032 | B37: MANOEL BELERIQUE | C37: 05.852.964/0001-81 | D37: Adriana | E37: 24 99233-9185 | F37: 25620-010 | G37: Rua Dom Pedro I | H37: 145 | I37: — | J37: Centro | K37: Petrópolis | L37: RJ | M37: Wiliam | N37: Supervisor 02 | O37: Sob Demanda | P37: C10 | Q37: 1805.91
A38: FC033 | B38: MARCA INFORMATICA | C38: 01.886.620/0001-32 | D38: Andrea | E38: 24 99993-4712 | F38: 25635-530 | G38: Rua Teresa | H38: 1515 | I38: Sala 25 | J38: Alto da Serra | K38: Petrópolis | L38: RJ | M38: Wiliam | N38: Supervisor 02 | O38: Sob Demanda | P38: C20 | Q38: 384.03
A39: FC034 | B39: NEW GROUP TELECOM | C39: 12.913.472/0001-14 | D39: Camila | E39: 24 99278-0366 | F39: 25680-176 | G39: Rua Professor Stroeler | H39: 428 | J39: Quarteirão Brasileiro | K39: Petrópolis | L39: RJ | M39: Brenda | N39: Coordenador ADM | O39: Sob Demanda | P39: C19 | Q39: 530.01
A40: FC038 | B40: POUSADA DE ARARAS - CONDOMINIO | C40: SEM CONTRATO | F40: 25725-022 | G40: Estrada Bernardo Coutinho | H40: 4570 | I40: Lote E | J40: Araras | K40: Petrópolis | L40: RJ | M40: Bernardo | N40: Supervisor 01 | O40: Bimestral | P40: B05 | Q40: 8635.76
A41: FC041 | B41: PRISCILA - CONDOMINIO | C41: 36.440.394/0001-46 | D41: Valdir | E41: 24 98833-9579 | F41: 25625-000 | G41: Rua Dr. Eugenio Barcellos | H41: 60 | J41: Valparaiso | K41: Petrópolis | L41: RJ | M41: Wiliam | N41: Supervisor 02 | O41: Sob Demanda | P41: C16 | Q41: 751.06
A42: FC042 | B42: REDETV | C42: SEM CONTRATO | D42: Vivian | E42: 24 98857-4814 | F42: 25620-030 | G42: Rua Paulo Barbosa | H42: 180 | I42: — | J42: Centro | K42: Petrópolis | L42: RJ | M42: Brenda | N42: Coordenador ADM | O42: Sob Demanda | P42: C27 | Q42: 0
A43: FC045 | B43: SESMARIAS - CONDOMINIO | C43: 18.995.780/0001-12 | D43: Vinícius Barros | E43: 21 992514607 | F43: 25645-312 | G43: Estrada do Samambaia | H43: 335 | I43: — | J43: Samambaia | K43: Petrópolis | L43: RJ | M43: Brenda | N43: Coordenador ADM | O43: Quinzenal | P43: A02 | Q43: 79431.92
A44: FC047 | B44: SULTEC | C44: 20.251.881/0001-20 | D44: Ana | E44: 24 98802-3120 | F44: 25635-530 | G44: Rua Teresa | H44: 1524 | I44: — | J44: Alto da Serra | K44: Petrópolis | L44: RJ | M44: Wiliam | N44: Supervisor 02 | O44: Bimestral | P44: C08 | Q44: 1962.31
A45: FC048 | B45: TARRAFAS SHOPPING - COMERCIAL | C45: 08.834.722/0001-53 | D45: Claudia | E45: 21 97223-1836 | F45: 25750-226 | G45: Rua União e Indústria | H45: 10395 | I45: — | J45: Itaipava | K45: Petrópolis | L45: RJ | M45: Bernardo | N45: Supervisor 01 | O45: Semanal | P45: A05 | Q45: 24977.75
A46: FC050 | B46: TOP HOUSE | C46: 05.941.573/0001-33 | D46: Claudia | E46: 24 2232-2450 | F46: 25745-120 | G46: Estrada Philuvio Cerqueira Rodrigues | H46: 1916 | I46: Área B | J46: Itaipava | K46: Petrópolis | L46: RJ | M46: Bernardo | N46: Supervisor 01 | O46: Mensal | P46: B02 | Q46: 12189.42
A47: FC052 | B47: VIA VISAO (MARQUESE) | C47: 40.261.476/0001-09 | D47: Carlos Alberto Lima da Silva | E47: 24 99259-5083 | F47: 25620-003 | G47: Rua do Imperador | H47: — | I47: — | J47: Centro | K47: Petrópolis | L47: RJ | M47: Brenda | N47: Coordenador ADM | O47: Sob Demanda | P47: C23 | Q47: 247.53
A48: FC053 | B48: ÓTICA ZEISS - 16 de Março | C48: 44.154.533/0001-01 | D48: Carlos Alberto Lima da Silva | E48: 24 99259-5083 | F48: 25620-040 | G48: Rua Dezesseis de Março | H48: 33 | I48: — | J48: Centro | K48: Petrópolis | L48: RJ | M48: Brenda | N48: Coordenador ADM | O48: Sob Demanda | P48: C24 | Q48: 247.35
A49: FC054 | B49: VIA VISÃO ( VILAREJO ) | C49: 40.261.476/0002-81 | D49: Carlos Alberto Lima da Silva | E49: 24 99259-5083 | F49: 25750-221 | G49: Estrada União e Indústria | H49: 10035 | I49: Loja A 142 | J49: Itaipava | K49: Petrópolis | L49: RJ | M49: Brenda | N49: Coordenador ADM | O49: Sob Demanda | P49: C25 | Q49: 247.29
A50: FC055 | B50: VILLAR IMPERIAL - CONDOMINIO | C50: 28.462.489/0001-32 | D50: Rosangela | E50: 24 99999-1747 | F50: 25655-152 | G50: Rua Coronel Veiga | H50: 733 | I50: — | J50: Valparaíso | K50: Petrópolis | L50: RJ | M50: Wiliam | N50: Supervisor 02 | O50: Sob Demanda | P50: C06 | Q50: 2201.89
...

Sheet Postos IA
A1: CODIGO | B1: COD CLIENTE | C1: CATEGORIA DE POSTO | D1: TURNO | E1: TIPO ESCALA | F1: QUANT. | G1: HORAS DIÁRIAS | H1: exigencia_nr32 | I1: exigencia_nr35 | J1: CESTA BASICA | K1: INSALUB / PERICULOSIDADE | L1: FERIADOS | M1: DESCRIÇÃO DA ESCALA - dia da semana + horario
A2: FC001 - LD-C/U | B2: FC001 | C2: LIMPADOR | D2: DIURNO | E2: C - menos de 44h | F2: UNICO | G2: 1 | H2: N/A | I2: N/A | J2: Roteiro ou Contagem | K2: N/A | L2: SEM COBERT | M2: Seg, Qua e Sex - 09:00 às 18:00 - Intervalo: 13h - 14h - Pausa: N/A - Folga: N/A
A3: FC003 - LD-C/U | B3: FC003 | C3: LIMPADOR | D3: DIURNO | E3: C - menos de 44h | F3: UNICO | G3: 0.33333333 | H3: N/A | I3: N/A | J3: Roteiro ou Contagem | K3: N/A | L3: COB CONTRATO | M3: Ter e Qui - 07:30 às 11:30 - Intervalo: N/A - Pausa: N/A - Folga: N/A
A4: FC004 - PD-C/U | B4: FC004 | C4: PORTEIRO | D4: DIURNO | E4: C - menos de 44h | F4: UNICO | G4: 0.54166667 | H4: N/A | I4: N/A | J4: Roteiro ou Contagem | K4: N/A | L4: COB CONTRATO | M4: Dom - 09:00 às 22:00 - Intervalo: 13h - 14h - Pausa: 17h - 17h15 - Folga: 7º Dom
A5: FC004 - PN-B/U | B5: FC004 | C5: PORTEIRO | D5: NOTURNO | E5: B - 44 horas | F5: UNICO | G5: 1.8333333 | H5: N/A | I5: N/A | J5: Cesta Gd | K5: N/A | L5: COB CONTRATO | M5: Seg à Dom - 22:00 às 06:20 - intervalo: 02h - 03h - Pausa: N/A - Folga: Quintas e 4º Dom
A6: FC004 - PN-C/1 | B6: FC004 | C6: PORTEIRO | D6: NOTURNO | E6: C - menos de 44h | F6: 1 | G6: 0.30555556 | H6: N/A | I6: N/A | J6: Roteiro ou Contagem | K6: N/A | L6: COB CONTRATO | M6: Quintas - 22:00 às 06:20 - intervalo: 02h - 03h - Pausa: N/A - Folga: N/A
A7: FC008 - LD-B/U | B7: FC008 | C7: LIMPADOR | D7: DIURNO | E7: B - 44 horas | F7: UNICO | G7: 1.8333333 | H7: N/A | I7: N/A | J7: Cesta Gd | K7: N/A | L7: SEM COBERT | M7: Seg à Sex - 07:30 às 16:30 / Sáb - 07:30 às 11:30 - Intervalo: 12h - 13h - Pausa: N/A - Folga: Domingos
A8: FC008 - PD-C/1 | B8: FC008 | C8: PORTEIRO | D8: DIURNO | E8: C - menos de 44h | F8: 1 | G8: 0.5 | H8: N/A | I8: N/A | J8: Roteiro ou Contagem | K8: N/A | L8: COB CONTRATO | M8: Dom - 07:00 às 19:00 - Intervalo: 11h - 12h - Pausa: 16h - 16h15 - Folga: 7º Dom
A9: FC008 - PD-C/2 | B9: FC008 | C9: PORTEIRO | D9: DIURNO | E9: C - menos de 44h | F9: 2 | G9: 1.6666667 | H9: N/A | I9: N/A | J9: Roteiro ou Contagem | K9: N/A | L9: COB CONTRATO | M9: Seg à Sex - 09:00 às 18:00 - Intervalo: 13h - 14h - Pausa: N/A - Folga: Sáb, Dom e Fer
A10: FC008 - PN-C/U | B10: FC008 | C10: PORTEIRO | D10: NOTURNO | E10: C - menos de 44h | F10: UNICO | G10: 1.0416667 | H10: N/A | I10: N/A | J10: Cesta Pq | K10: N/A | L10: COB CONTRATO | M10: Sáb - 18:00 às 07:00 / Dom e Feriados - 19:00 às 07:00 - Intervalo: 22h - 23h - Pausa: 03h - 03h15 - Folga: N/A
A11: FC009a - LD-C/1 | B11: FC009a | C11: LIMPADOR | D11: DIURNO | E11: C - menos de 44h | F11: 1 | G11: 0.41666667 | H11: NR32 | I11: N/A | J11: Roteiro ou Contagem | K11: 0.2 | L11: SEM COBERT | M11: Seg à Sex - 14:00 às 16:00 - Intervalo: N/A - Pausa: N/A - Folga: N/A
A12: FC009a - LD-C/2 | B12: FC009a | C12: LIMPADOR | D12: DIURNO | E12: C - menos de 44h | F12: 2 | G12: 0.083333333 | H12: NR32 | I12: N/A | J12: Roteiro ou Contagem | K12: 0.2 | L12: SEM COBERT | M12: Sáb - 10:00 às 12:00- Intervalo: N/A - Pausa: N/A - Folga: N/A
A13: FC009b - LD-B/U | B13: FC009b | C13: LIMPADOR | D13: DIURNO | E13: B - 44 horas | F13: UNICO | G13: 1.8333333 | H13: NR32 | I13: N/A | J13: Cesta Gd | K13: 0.2 | L13: SEM COBERT | M13: Seg à Sex - 07:00 às 16:00 / Sáb - 07:00 às 11:00 - Intervalo: 12h - 13h - Pausa: N/A - Folga: Domingos
A14: FC009c - LD-C/1 | B14: FC009c | C14: LIMPADOR | D14: DIURNO | E14: C - menos de 44h | F14: 1 | G14: 0.41666667 | H14: NR32 | I14: N/A | J14: Roteiro ou Contagem | K14: 0.2 | L14: SEM COBERT | M14: Seg à Sex - 13:45 às 15:45 - Intervalo: N/A - Pausa: N/A - Folga: N/A
A15: FC009c - LD-C/2 | B15: FC009c | C15: LIMPADOR | D15: DIURNO | E15: C - menos de 44h | F15: 2 | G15: 0.083333333 | H15: NR32 | I15: N/A | J15: Roteiro ou Contagem | K15: 0.2 | L15: SEM COBERT | M15: Sáb - 09:00 às 11:00 - Intervalo: N/A - Pausa: N/A - Folga: N/A
A16: FC009d - LD-C/U | B16: FC009d | C16: LIMPADOR | D16: DIURNO | E16: C - menos de 44h | F16: UNICO | G16: 1.40625 | H16: NR32 | I16: N/A | J16: Roteiro ou Contagem | K16: 0.2 | L16: SEM COBERT | M16: Seg à Sáb - 06:30 às 11:30 - Intervalo: N/A - Pausa: N/A - Folga: N/A
A17: FC009e - LD-B/1 | B17: FC009e | C17: LIMPADOR | D17: DIURNO | E17: B - 44 horas | F17: 1 | G17: 1.8333333 | H17: NR32 | I17: N/A | J17: Cesta Gd | K17: 0.2 | L17: SEM COBERT | M17: Seg à Sex - 06:30 às 15:30 / Sáb - 07:00 às 11:00 - Intervalo: 11:00 - 12:00 - Pausa: N/A - Folga: Dom e Fer
A18: FC009e - LD-B/2 | B18: FC009e | C18: LIMPADOR | D18: DIURNO | E18: B - 44 horas | F18: 2 | G18: 1.8333333 | H18: NR32 | I18: N/A | J18: Cesta Gd | K18: 0.2 | L18: SEM COBERT | M18: Seg à Sex 08:00 ás 17:00 / Sáb 08:00 às 12:00 - Intervalo 13:00 -14:00 - Pausa N/A - Folga: Dom e Fer
A19: FC009f - LD-C/U | B19: FC009f | C19: LIMPADOR | D19: DIURNO | E19: C - menos de 44h | F19: UNICO | G19: 1.8333333 | H19: NR32 | I19: N/A | J19: Vale Refeição | K19: 0.2 | L19: SEM COBERT | M19: Seg à Sáb - 07:00 às 12:00 - Intervalo: N/A - Pausa: N/A - Folga: Domingos
A20: FC009g - LD-B/U | B20: FC009g | C20: LIMPADOR | D20: DIURNO | E20: B - 44 horas | F20: UNICO | G20: 1.8333333 | H20: NR32 | I20: N/A | J20: Vale Refeição | K20: 0.2 | L20: SEM COBERT | M20: Seg à Qui - 07:00 às 16:00 / Sex - 07:00 às 15:00 / Sáb - 07:00 às 12:00 - Intervalo: 11h - 12h - Pausa: N/A - Folga: Domingos
A21: FC009h - LD-C/U | B21: FC009h | C21: LIMPADOR | D21: DIURNO | E21: C - menos de 44h | F21: UNICO | G21: 0.91666667 | H21: NR32 | I21: N/A | J21: Cesta Pq | K21: 0.2 | L21: SEM COBERT | M21: Seg à Sex - 07:00 às 11:00 / Sáb - 08:00 às 10:00 - Intervalo: N/A - Pausa: N/A - Folga: Domingo
A22: FC009i - LD-C/U | B22: FC009i | C22: LIMPADOR | D22: DIURNO | E22: C - menos de 44h | F22: UNICO | G22: 1.25 | H22: NR32 | I22: N/A | J22: Cesta Pq | K22: 0.2 | L22: SEM COBERT | M22: Seg à Sáb - 07:00 às 12:00 - Intervalo: N/A - Pausa: N/A - Folga: Domingo
A23: FC009j - LD-B/U | B23: FC009j | C23: LIMPADOR | D23: DIURNO | E23: B - 44 horas | F23: UNICO | G23: 1.8333333 | H23: NR32 | I23: N/A | J23: Cesta Gd | K23: 0.2 | L23: SEM COBERT | M23: Seg à Qui - 06:30 às 15:30 / Sex - 06:30 às 14:30 / Sáb - 07:00 às 12:00 - Intervalo: 12h - 13h - Pausa: N/A - Folga: Domingos
A24: FC009k - LD-C/U | B24: FC009k | C24: LIMPADOR | D24: DIURNO | E24: C - menos de 44h | F24: UNICO | G24: 1.25 | H24: NR32 | I24: N/A | J24: Cesta Pq | K24: 0.2 | L24: SEM COBERT | M24: Seg à Sáb - 07:00 às 12:00 - Intervalo: N/A - Pausa: N/A - Folga: Domingo
A25: FC009l - LD-C/U | B25: FC009l | C25: LIMPADOR | D25: DIURNO | E25: C - menos de 44h | F25: UNICO | G25: 1.0416667 | H25: NR32 | I25: N/A | J25: Cesta Pq | K25: 0.2 | L25: SEM COBERT | M25: Seg à Sex - 07:00 às 12:00 - Intervalo: N/A - Pausa: N/A - Folga: Sab e Dom
A26: FC009m - LD-C/1 | B26: FC009m | C26: LIMPADOR | D26: DIURNO | E26: C - menos de 44h | F26: 1 | G26: 0.70833333 | H26: NR32 | I26: N/A | J26: Roteiro ou Contagem | K26: 0.2 | L26: SEM COBERT | M26: Seg, Qua e Sex - 07:00 às 13:00 - Intervalo: N/A - Pausa: N/A - Folga: N/A
A27: FC009m - LD-C/2 | B27: FC009m | C27: LIMPADOR | D27: DIURNO | E27: C - menos de 44h | F27: 2 | G27: 0.5 | H27: N/A | I27: N/A | J27: Roteiro ou Contagem | K27: 0.2 | L27: SEM COBERT | M27: Ter e Qui - 07:00 às 11:00 - Intervalo: N/A - Pausa: N/A - Folga: N/A
A28: FC009m - LD-C/3 | B28: FC009m | C28: LIMPADOR | D28: DIURNO | E28: C - menos de 44h | F28: 3 | G28: 0.20833333 | H28: N/A | I28: N/A | J28: Roteiro ou Contagem | K28: 0.2 | L28: SEM COBERT | M28: Sáb - 07:00 às 12:00 - Intervalo: N/A - Pausa: N/A - Folga: N/A
A29: FC009n - LD-C/U | B29: FC009n | C29: LIMPADOR | D29: DIURNO | E29: C - menos de 44h | F29: UNICO | G29: 1.25 | H29: NR32 | I29: N/A | J29: Cesta Pq | K29: 0.2 | L29: SEM COBERT | M29: Seg à Sáb - 07:00 às 12:00 - Intervalo: N/A - Pausa: N/A - Folga: Domingo
A30: FC009o - LD-C/U | B30: FC009o | C30: LIMPADOR | D30: DIURNO | E30: C - menos de 44h | F30: UNICO | G30: 1.25 | H30: NR32 | I30: N/A | J30: Cesta Pq | K30: 0.2 | L30: SEM COBERT | M30: Seg à Sáb - 07:00 às 12:00 - Intervalo: N/A - Pausa: N/A - Folga: Domingos
A31: FC009p - LD-B/U | B31: FC009p | C31: LIMPADOR | D31: DIURNO | E31: B - 44 horas | F31: UNICO | G31: 1.8333333 | H31: NR32 | I31: N/A | J31: Cesta Gd | K31: 0.2 | L31: COB EXTRA | M31: Seg à Sáb - 07:00 às 15:20 - Intervalo: 11h - 12h - Pausa: N/A - Folga: Domingos
A32: FC009q - LD-B/U | B32: FC009q | C32: LIMPADOR | D32: DIURNO | E32: B - 44 horas | F32: UNICO | G32: 1.8333333 | H32: NR32 | I32: N/A | J32: Cesta Gd | K32: 0.2 | L32: SEM COBERT | M32: Seg à Sex - 07:00 às 16:00 / Sáb - 07:00 às 11:00 - Intervalo:12:00 às 13:00 - Pausa: N/A - Folga: Domingo
A33: FC009r - LD-C/U | B33: FC009r | C33: LIMPADOR | D33: DIURNO | E33: C - menos de 44h | F33: UNICO | G33: 1.2708333 | H33: NR32 | I33: N/A | J33: Cesta Pq | K33: 0.2 | L33: SEM COBERT | M33: Seg à Sáb - 07:00 às 12:00 - Intervalo: N/A - Pausa: N/A - Folga: Domingo
A34: FC009s - LD-C/U | B34: FC009s | C34: LIMPADOR | D34: DIURNO | E34: C - menos de 44h | F34: UNICO | G34: 1.2083333 | H34: N/A | I34: N/A | J34: Cesta Gd | K34: 0.2 | L34: SEM COBERT | M34: Seg, Qua e Sex 07:00 às 11:00, Ter e Qui 07:00 às 13:00 e Sáb 07:00 às 12:00 - Intervalo: N/A - Pausa: N/A - Folga: Dom
A35: FC009t - LD-B/U | B35: FC009t | C35: LIMPADOR | D35: DIURNO | E35: B - 44 horas | F35: UNICO | G35: 1.8333333 | H35: NR32 | I35: N/A | J35: Cesta Gd | K35: 0.2 | L35: SEM COBERT | M35: Seg à Qui - 06:30 às 15:30 / Sex - 06:30 às 14:30 / Sáb - 07:00 às 12:00 - Intervalo: 12h - 13h - Pausa: N/A - Folga: Domingos
A36: FC009u - LD-C/U | B36: FC009u | C36: LIMPADOR | D36: DIURNO | E36: C - menos de 44h | F36: UNICO | G36: 1.25 | H36: NR32 | I36: N/A | J36: Cesta Pq | K36: 0.2 | L36: SEM COBERT | M36: Seg à Sáb - 07:00 às 12:00 - Intervalo: N/A - Pausa: N/A - Folga: Domingo
A37: FC010 - LD-C/1 | B37: FC010 | C37: LIMPADOR | D37: DIURNO | E37: C - menos de 44h | F37: 1 | G37: 0.64583333 | H37: N/A | I37: N/A | J37: Roteiro ou Contagem | K37: N/A | L37: SEM COBERT | M37: Seg, Qua e Sex - 12:00 às 16:00 - Intervalo: N/A - Pausa: N/A - Folga: N/A
A38: FC010 - LD-C/2 | B38: FC010 | C38: LIMPADOR | D38: DIURNO | E38: C - menos de 44h | F38: 2 | G38: 0.33333333 | H38: N/A | I38: N/A | J38: Roteiro ou Contagem | K38: N/A | L38: SEM COBERT | M38: Ter e Qui - 12:00 às 16:00 - Intervalo: N/A - Pausa: N/A - Folga: N/A
A39: FC011 - LD-B/1 | B39: FC011 | C39: LIMPADOR | D39: DIURNO | E39: B - 44 horas | F39: 1 | G39: 1.8333333 | H39: N/A | I39: N/A | J39: Cesta Gd | K39: N/A | L39: COMPENSAÇÃO | M39: Seg à Dom - 08:00 às 16:20 - Intervalo: 12h - 13h - Pausa: N/A - Folga: Sáb e Dom alternado
A40: FC011 - LD-B/2 | B40: FC011 | C40: LIMPADOR | D40: DIURNO | E40: B - 44 horas | F40: 2 | G40: 1.8333333 | H40: N/A | I40: N/A | J40: Cesta Gd | K40: N/A | L40: COMPENSAÇÃO | M40: Seg à Dom - 08:00 às 16:20 - Intervalo: 12h - 13h - Pausa: N/A - Folga: Sáb e Dom alternado
...

Sheet Funcionarios IA
A1: Matrc | B1: nome | C1: telefone_principal | D1: is_whatsapp | E1: telefone_secundario | F1: Carteira de Trabalho | G1: CPF | H1: Nível de Atuação | I1: turno | J1: tipo de escala | K1: cep | L1: logradouro | M1: numero | N1: bairro | O1: cidade | P1: uf | Q1: status_cadastro | R1: Vencimento Férias | S1: tipo_contratacao | T1: horas_contratadas | U1: categoria_cargo | V1: situacao_afastamento | W1: data_exame_admissional_aso | X1: data_retorno_aso | Y1: data_integracao | Z1: Admissão | AA1: Prazo Experiência | AB1: Vencimento Férias | AC1: possui_nr32 | AD1: vencimento_nr32
A2: AG0477 | B2: ADRIANA DE FATIMA DE JESUS | C2: (24) 992071404 | F2: 01195073/05770 - RJ | G2: 11950735770 | H2: Operacional | J2: 6x1 | K2: 25715-410 | L2: SERVIDÃO SEBASTIÃO PLACIDINO DE CARVALHO | M2: 34 | N2: VALE DO CARANGOLA | O2: Petrópolis | P2: RJ | Q2: ativo | R2: 46177 | S2: Mensalista | T2: 1.8333333 | U2: Limpador | V2: Disponivel | X2: 46324 | Z2: 41065 | AB2: 46177
A3: FC0277 | B3: ADRIANA DE JESUS BRITO | C3: (24) 99335-0097 | F3: 01016730/03732 - RJ | G3: 10167303732 | H3: Operacional | J3: 6x1 | K3: 25715-300 | L3: RUA MANOEL LUIZ FERREIRA | M3: 0 | N3: CARANGOLA | O3: Petrópolis | P3: RJ | Q3: ativo | R3: 46482 | S3: Mensalista | T3: 1.8333333 | U3: Limpador | V3: Disponivel | X3: 46478 | Z3: 46118 | AB3: 46482
A4: AG0840 | B4: ALESSANDRA DE ASSUMPÇÃO CHAVES | C4: (21) 986029413 | E4: (21) 25127712 | F4: 01017192/02786 - RJ | G4: 10171922786 | H4: Operacional | J4: 6x1 | K4: 23585-370 | L4: RUA SERROLANDIA | M4: S/N | N4: PACIENCIA | O4: Rio de Janeiro | P4: RJ | Q4: ativo | R4: 46277 | S4: Mensalista | T4: 1.8333333 | U4: Outros | V4: Disponivel | X4: 46323 | Z4: 42626 | AB4: 46277
A5: AG0997 | B5: ALEX BORGES NOGUEIRA | C5: (24) 992463988 | F5: 01062616/08716 - RJ | G5: 10626168716 | H5: Operacional | J5: 12x36 | K5: 25720-001 | L5: SERVIDÃO ARLINDO TEIVO SOARES | M5: 106 | N5: ROSEIRAL | O5: Petrópolis | P5: RJ | Q5: ativo | R5: 46289 | S5: Mensalista | T5: 1.8333333 | U5: Portaria | V5: Disponivel | X5: 46546 | Z5: 43733 | AB5: 46289
A6: FC0005 | B6: ALEXSANDRO PERONI VIEIRA | C6: (24) 99234-6446 | F6: 01371030/02781 - RJ | G6: 13710302781 | H6: Operacional | J6: 6x1 | K6: 25715-060 | L6: RUA HERMOGENIO SILVA | M6: 1923 | N6: RETIRO | O6: Petrópolis | P6: RJ | Q6: ativo | R6: 45686 | S6: Mensalista | T6: 44:00 hs | U6: Limpador | V6: INSS | X6: afastamento | Z6: 45321 | AB6: 45686
A7: FC0179 | B7: ALINE DE SOUZA SOARES | C7: (24) 993227088 | F7: 01730641/00750 - RJ | G7: 17306410750 | H7: Operacional | J7: 12x36 | K7: 25715-000 | L7: SERVIDÃO ANTONIO RAMOS DOS SANTOS | M7: 36 | N7: RETIRO | O7: Petrópolis | P7: RJ | Q7: ativo | R7: 46083 | S7: Mensalista | T7: 44:00 hs | U7: Limpador | V7: Disponivel | X7: 46426 | Z7: 45719 | AB7: 46083
A8: AG0921 | B8: ALINE VIANA COUTO | C8: (21) 96675-0219 | F8: 01308045/02712 - RJ | G8: 13080452712 | H8: Operacional | J8: 6x1 | K8: 23585-370 | L8: RUA SERROLANDIA | M8: S/N | N8: PACIENCIA | O8: Rio de Janeiro | P8: RJ | Q8: ativo | R8: 46599 | S8: Mensalista | T8: 1.8333333 | U8: Outros | V8: Disponivel | X8: 46352 | Z8: 43313 | AB8: 46599
A9: AG1068 | B9: AMANDA MAXIMIANA DA SILVA | C9: (21) 97738-4388 | F9: 01819358/00702 - RJ | G9: 18193580702 | H9: Operacional | J9: 6x1 | K9: 21320-050 | L9: RUA ANTONIA | M9: 4 | N9: PRACA SECA | O9: Rio de Janeiro | P9: RJ | Q9: ativo | R9: 46549 | S9: Mensalista | T9: 1.8333333 | U9: Outros | V9: Disponivel | X9: 46394 | Z9: 43994 | AB9: 46549
A10: AG0910 | B10: AMARILDO PONTES DOS SANTOS | C10: (24) 992802008 | E10: (24) 22710283 | F10: 09929262/00040 - RJ | G10: 76799158734 | H10: Operacional | J10: 6x1 | K10: 25882-000 | L10: RUA JUVENAL PORTUGAL | M10: 375 | N10: ANTA | O10: Sapucaia | P10: RJ | Q10: ativo | R10: 43631 | S10: Mensalista | T10: 1.8333333 | U10: Limpador | V10: INSS | X10: afastamento | Z10: 43267 | AB10: 43631
A11: AG0951 | B11: ANA LUCIA BARRETO FELIZARDO DA SILVA | C11: (24) 988118514 | E11: (24) 22332719 | F11: 00067001/00766 - RJ | G11: 00670010766 | H11: Operacional | J11: 6x1 | K11: 25680-003 | L11: RUA PAULINO AFONSO | M11: S/N | N11: CENTRO | O11: Petrópolis | P11: RJ | Q11: ativo | R11: 46081 | S11: Mensalista | T11: 1.8333333 | U11: Limpador | V11: INSS | X11: afastamento | Z11: 43525 | AB11: 46081
A12: AG0770 | B12: ANA LUCIA FRAGA | C12: (24) 992070795 | E12: (24) 22371830 | F12: 00792151/06742 - RJ | G12: 07921516742 | H12: Gestão | J12: 6x1 | K12: 25640-010 | L12: RUA ANTONIO SOARES PINTO | M12: 245 | N12: ALTO DA SERRA | O12: Petrópolis | P12: RJ | Q12: ativo | R12: 46507 | S12: Mensalista | T12: 1.8333333 | U12: Gestão | V12: Disponivel | X12: 46328 | Z12: 42125 | AB12: 46507
A13: MC0059 | B13: ANA PAULA DOS SANTOS XAVIER | C13: (24) 988246948 | E13: (24) 22633841 | F13: 00759581/05762 - RJ | G13: 07595815762 | H13: Operacional | J13: 6x1 | K13: 25850-000 | L13: RUA FERNANDO BARROS FRANCO | M13: 17 | N13: LAVA PES | O13: Paraíba do Sul | P13: RJ | Q13: ativo | R13: 45716 | S13: Mensalista | T13: 1.8333333 | U13: Limpador | V13: INSS | X13: afastamento | Z13: 45351 | AB13: 45716
A14: FC0311 | B14: ANA PAULA MAYWORM DA SILVA | C14: (24) 98804-9989 | F14: 01619904/04703 - RJ | G14: 16199044703 | H14: Operacional | J14: 6x1 | K14: 25710-229 | L14: RUA JOAQUIM JOAO DE OLIVEIRA | M14: 220 | N14: CASCATINHA | O14: Petrópolis | P14: RJ | Q14: ativo | R14: 46580 | S14: Mensalista | T14: 1.8333333 | U14: Limpador | V14: Disponivel | X14: 46576 | Z14: 46216 | AA14: 45dd | AB14: 46580
A15: AG0786 | B15: ANDERSON DOS SANTOS MACHADO | C15: (24) 988149632 | F15: 00982427/05738 - RJ | G15: 09824275738 | H15: Operacional | J15: 12x36 | K15: 25615-071 | L15: RUA ELYZIO ALVES | M15: 250 | N15: CAXAMBU | O15: Petrópolis | P15: RJ | Q15: ativo | R15: 46203 | S15: Mensalista | T15: 1.8333333 | U15: Portaria | V15: Disponivel | X15: 46471 | Z15: 42186 | AB15: 46203
A16: FC0260 | B16: ANDERSON FARIAS FERREIRA | C16: (24) 993244491 | F16: 00792168/04700 - RJ | G16: 07921684700 | H16: Operacional | J16: 6x1 | K16: 25651-010 | L16: AVENIDA AMARAL PEIXOTO | M16: 895 | N16: QUITANDINHA | O16: Petrópolis | P16: RJ | Q16: ativo | R16: 46419 | S16: Mensalista | T16: 1.8333333 | U16: Limpador | V16: Disponivel | X16: 46415 | Z16: 46055 | AB16: 46419
A17: FC0210 | B17: ANDREA SOUZA DOS SANTOS | C17: (21) 99204-2520 | F17: 09013864/03768 - RJ | G17: 90138643768 | H17: Operacional | J17: 6x1 | K17: 26260-555 | L17: RUA ALVARO MACEDO | M17: 84 | N17: LUZ | O17: Nova Iguaçu | P17: RJ | Q17: ativo | R17: 46225 | S17: Intermitente | T17: 00:00 hs | U17: Limpador | V17: Disponivel | X17: 46574 | Z17: 45861 | AB17: 46225
A18: AG1276 | B18: ANDRELINO DOS SANTOS BARCELOS | C18: (21) 98246-0510 | F18: 00982959/05757 - RJ | G18: 09829595757 | H18: Operacional | J18: 6x1 | K18: 26587-335 | L18: RUA CORONEL AZEVEDO JUNIOR | M18: 1069 | N18: CHATUBA | O18: Rio de Janeiro | P18: RJ | Q18: ativo | R18: 46427 | S18: Mensalista | T18: 1.8333333 | U18: Limpador | V18: Disponivel | X18: 46399 | Z18: 44602 | AB18: 46427
A19: FC0168 | B19: ANNA KLARA DE OLIVEIRA DA COSTA PINTO | C19: (22) 98804-2125 | F19: 00643845/05776 - RJ | G19: 06438455776 | H19: Operacional | J19: 6x1 | K19: 28620-250 | L19: RUA AMAPA | M19: 28 | N19: OLARIA | O19: Nova Friburgo | P19: RJ | Q19: ativo | R19: 46069 | S19: Intermitente | T19: 00:00 hs | U19: Limpador | V19: Disponivel | X19: 46475 | Z19: 45705 | AB19: 46069
A20: MC0008 | B20: ANTONIO MARCOS MACHADO DESIDERIO | C20: (24) 992652363 | F20: 01408754/08783 - RJ | G20: 14087548783 | H20: Operacional | J20: 12x36 | K20: 25680-250 | L20: RUA JOAO BALTER | M20: S/N | N20: QUARTEIRAO BRASILEIR | O20: Petrópolis | P20: RJ | Q20: ativo | R20: 46199 | S20: Mensalista | T20: 1.8333333 | U20: Portaria | V20: Disponivel | X20: 46540 | Z20: 44009 | AB20: 46199
A21: AG1334 | B21: ANYA OLIVEIRA FONTOURA | C21: (85) 988981020 | F21: 00044221/07382 - RJ | G21: 00442217382 | H21: Gestão | J21: 6x1 | K21: 60135-270 | L21: RUA VICENTE LINHARES | M21: 654 | N21: ALDEOTA | O21: Fortaleza | P21: CE | Q21: ativo | R21: 46276 | S21: Mensalista | T21: 1.8333333 | U21: Outros | V21: Disponivel | X21: 46238 | Z21: 44816 | AB21: 46276
A22: AG1233 | B22: ARIANA ANDRADE ARCANJO | C22: (24) 992427239 | E22: (24) 20204511 | F22: 01477089/07723 - RJ | G22: 14770897723 | H22: Operacional | J22: 6x1 | K22: 25645-705 | L22: RUA MANOEL FRANCISCO DE PAULA | M22: 19 | N22: SIMERIA | O22: Petrópolis | P22: RJ | Q22: ativo | R22: 46305 | S22: Mensalista | T22: 1.8333333 | U22: Limpador | V22: Disponivel | X22: 46281 | Z22: 44480 | AB22: 46305
A23: AG1374 | B23: BARBARA DUARTE | C23: (24) 992722114 | F23: 15701554/00748 - RJ | G23: 15701554708 | H23: Operacional | J23: 6x1 | K23: 25745-690 | L23: ESTRADA MINISTRO SALGADO FILHO | M23: 4115 | N23: VALE DO CUIABA | O23: Petrópolis | P23: RJ | Q23: ativo | R23: 46140 | S23: Mensalista | T23: 1.8333333 | U23: Limpador | V23: Disponivel | X23: 46289 | Z23: 45045 | AB23: 46140
A24: FC0305 | B24: BEATRIZ NOEMIA DA SILVA ROCHA DOS SANTOS ADRIANO | C24: (24) 974024072 | E24: (24) 22488951 | F24: 01610916/08750 - RJ | G24: 16109168750 | H24: Operacional | J24: 6x1 | K24: 25716-231 | L24: TRAVESSA CANDIDO BORSATO | M24: 720 | N24: CASCATINHA | O24: Petrópolis | P24: RJ | Q24: ativo | R24: 46560 | S24: Mensalista | T24: 1.8333333 | U24: Limpador | V24: Disponivel | X24: 46559 | Z24: 46196 | AA24: 45dd | AB24: 46560
A25: AG0835 | B25: BERNARDO DE SOUZA RAMOS LAGO | C25: (24) 988074779 | E25: (24) 22379380 | F25: 08111245/09715 - RJ | G25: 81112459715 | H25: Gestão | J25: 6x1 | K25: 25675-111 | L25: RUA NOSSA SENHORA DAS GRAÇAS | M25: 205 | N25: MOSELA | O25: Petrópolis | P25: RJ | Q25: ativo | R25: 46507 | S25: Mensalista | T25: 1.8333333 | U25: Gestão | V25: Disponivel | X25: 46559 | Z25: 42491 | AB25: 46507
A26: AG1450 | B26: BIANCA MARIA ALVES DE JESUS | C26: (24) 99298-6690 | F26: 02191435/03781 - RJ | G26: 21914353781 | H26: Operacional | J26: 6x1 | K26: 25720-062 | L26: ESTRADA UNIAO INDUSTRIA | M26: 2501 | N26: CORREAS | O26: Petrópolis | P26: RJ | Q26: ativo | R26: 46376 | S26: Mensalista | T26: 1.8333333 | U26: Limpador | V26: Disponivel | X26: 46352 | Z26: 45281 | AB26: 46376
A27: AG0855 | B27: BRENDA NASCIMENTO NICOLAU | C27: (24) 992549907 | E27: (24) 22918382 | F27: 01810169/02754 - RJ | G27: 18101692754 | H27: Gestão | J27: 6x1 | K27: 25715-391 | L27: SERVIDÃO JOAQUIM AFONSO DA SILVA | M27: 13 | N27: VALE DO CARANGOLA | O27: Petrópolis | P27: RJ | Q27: ativo | R27: 46447 | S27: Mensalista | T27: 1.8333333 | U27: Gestão | V27: Disponivel | X27: 46268 | Z27: 42796 | AB27: 46447
A28: FC0313 | B28: BRUNO ANDRE DE SOUZA | C28: (24) 98835-5420 | E28: (24) 98864-6605 | F28: 01443609/01708 - RJ | G28: 14436091708 | H28: Operacional | J28: 6x1 | K28: 25670-011 | L28: RUA PROFESSOR JOSE REUTHER | M28: 165 | N28: MOSELA | O28: Petrópolis | P28: RJ | Q28: ativo | R28: 46587 | S28: Mensalista | T28: 1.8333333 | U28: Limpador | V28: Disponivel | X28: 46583 | Z28: 46223 | AA28: 45dd | AB28: 46587
A29: MC0103 | B29: CARLOS EDUARDO MONTEIRO BRANDAO | C29: (24) 98870-0570 | E29: (24) 2235-6804 | F29: 00446550/05799 - RJ | G29: 04466505799 | H29: Operacional | J29: 12x36 | K29: 25600-001 | L29: ESTRADA RIO NEGRO | M29: S/N | N29: POSSE | O29: Petrópolis | P29: RJ | Q29: ativo | R29: 46531 | S29: Mensalista | T29: 1.8333333 | U29: Portaria | V29: Disponivel | X29: 46528 | Z29: 46167 | AB29: 46531
A30: FC0185 | B30: CARLOS HENRIQUE DA FONSECA BARBOSA | C30: (24) 98823-2865 | F30: 00060694/09712 - RJ | G30: 00606949712 | H30: Operacional | J30: 6x1 | K30: 25730-500 | L30: ESTRADA DO PALMITAL | M30: 833 | N30: NOGUEIRA | O30: Petrópolis | P30: RJ | Q30: ativo | R30: 46095 | S30: Mensalista | T30: 1.8333333 | U30: Manutenção | V30: INSS | X30: afastamento | Z30: 45731 | AB30: 46095
A31: AG1091 | B31: CARMEN LUCIA SCHMITZ | C31: (24) 99912-9606 | F31: 00229358/03732 - RJ | G31: 02293583732 | H31: Operacional | J31: 6x1 | K31: 25716-363 | L31: ESTRADA VICENZO RIVETTI | M31: 505 | N31: CARANGOLA | O31: Petrópolis | P31: RJ | Q31: ativo | R31: 46287 | S31: Mensalista | T31: 1.8333333 | U31: Limpador | V31: Disponivel | X31: 46275 | Z31: 44097 | AB31: 46287
A32: AG1436 | B32: CASSIANO SIESS PEREIRA | C32: (24) 981257222 | F32: 01734347/06785 - RJ | G32: 17343476785 | H32: Operacional | J32: 12x36 | K32: 25720-210 | L32: RUA CAPITAO AMANCIO DE SOUZA COUTINHO | M32: 384 | N32: CORREAS | O32: Petrópolis | P32: RJ | Q32: ativo | R32: 46336 | S32: Mensalista | T32: 1.8333333 | U32: Portaria | V32: Disponivel | X32: 46519 | Z32: 45241 | AB32: 46336
A33: AG0907 | B33: CELMA MARIA DA SILVA | C33: (24) 988195587 | E33: (24) 22457105 | F33: 00003587/02748 - RJ | G33: 00035872748 | H33: Operacional | J33: 6x1 | K33: 25715-200 | L33: RUA VIRGILIO DE SA PEREIRA JUNIOR | M33: 648 | N33: ROSEIRAL | O33: Petrópolis | P33: RJ | Q33: ativo | R33: 46683 | S33: Mensalista | T33: 1.8333333 | U33: Limpador | V33: INSS | X33: afastamento | Z33: 43254 | AB33: 46683
A34: AG1361 | B34: CINTIA RIBEIRO DE MATTOS COSTA | C34: (24) 992090676 | E34: (24) 988787288 | F34: 00014109/00145 - RJ | G34: 12688270702 | H34: Gestão | J34: 6x1 | K34: 25615-241 | L34: CAMINHO MONTE FLORIDO | M34: 279 | N34: ESTRADA DA SAUDADE | O34: Petrópolis | P34: RJ | Q34: ativo | R34: 46055 | S34: Mensalista | T34: 1.8333333 | U34: Outros | V34: Disponivel | X34: 46394 | Z34: 44960 | AB34: 46055
A35: FC0104 | B35: CLAUDIA REGINA VIEIRA | C35: (21) 97708-6070 | F35: 01006766/00738 - RJ | G35: 10067660738 | H35: Operacional | J35: 6x1 | K35: 26051-670 | L35: RUA ITAOCA | M35: 4 | N35: PARQUE SAO CARLOS | O35: Nova Iguaçu | P35: RJ | Q35: ativo | R35: 46273 | S35: Intermitente | T35: 00:00 hs | U35: Limpador | V35: Disponivel | X35: 46258 | Z35: 45544 | AB35: 46273
A36: MC0032 | B36: CLAUDIO MARCIO ARAUJO SILVA | C36: (24) 988226256 | E36: (24) 22435292 | F36: 00974193/07717 - RJ | G36: 09741937717 | H36: Operacional | J36: 12x36 | K36: 25655-158 | L36: RUA CORONEL VEIGA | M36: 890 | N36: CORONEL VEIGA | O36: Petrópolis | P36: RJ | Q36: ativo | R36: 45935 | S36: Mensalista | T36: 1.8333333 | U36: Portaria | V36: INSS | X36: afastamento | Z36: 44475 | AB36: 45935
A37: MC0002 | B37: CLEBER MARTINS SCHMIDT | C37: (24) 988327751 | E37: (24) 22351442 | F37: 00866569/08710 - RJ | G37: 08665698710 | H37: Operacional | J37: 12x36 | K37: 25650-480 | L37: RUA RIO GRANDE DO NORTE | M37: 35 | N37: QUITANDINHA | O37: Petrópolis | P37: RJ | Q37: ativo | R37: 46096 | S37: Mensalista | T37: 1.8333333 | U37: Portaria | V37: Disponivel | X37: 46420 | Z37: 43906 | AB37: 46096
A38: AG0142 | B38: CREUSA JUREMA DOS SANTOS | E38: (24) 22475898 | F38: 00007301/00101 - RJ | G38: 044260447-58 | H38: Operacional | J38: 6x1 | K38: 25600-000 | L38: RUA FERNANDES VIEIRA | M38: SN | N38: RETIRO | O38: Petrópolis | P38: RJ | Q38: ativo | R38: 46264 | S38: Mensalista | T38: 1.8333333 | U38: Limpador | V38: INSS | X38: afastamento | Z38: 39497 | AB38: 46264
A39: FC0236 | B39: CRISTIANE DEMELVOU | C39: (24) 98833-3972 | E39: (24) 99219-1324 | F39: 00564591/07774 - RJ | G39: 05645917774 | H39: Operacional | J39: 6x1 | K39: 25645-705 | L39: RUA VITAL BRASIL | M39: 123 | N39: SAO SEBASTIAO | O39: Petrópolis | P39: RJ | Q39: ativo | R39: 46312 | S39: Mensalista | T39: 1.8333333 | U39: Limpador | V39: Disponivel | X39: 46310 | Z39: 45948 | AB39: 46312
A40: AG0479 | B40: CRISTINA APARECIDA DE SOUZA DEOLINDO | C40: (24) 992138158 | E40: (24) 22488753 | F40: 09819437/02704 - RJ | G40: 981943727-04 | H40: Operacional | J40: 6x1 | K40: 25645-090 | L40: RUA LUIZ XAVIER | M40: 78 | N40: SIMERIA | O40: Petrópolis | P40: RJ | Q40: ativo | R40: 46186 | S40: Mensalista | T40: 1.8333333 | U40: Limpador | V40: Disponivel | X40: 46398 | Z40: 41074 | AB40: 46186
...

Sheet ALOCAÇÃO IA
A1: CODIGO POSTO | B1: CPF
A2: FC062 - LD-B/1 | B2: 11950735770
A3: FC077 - LD-B/U | B3: 10167303732
A4: FC048 - PD-A/2 | B4: 10171922786
A5: FC074 - LD-A/1 | B5: 17306410750
A6: FC011 - LD-B/1 | B6: 07921684700
A7: FC048 - PN-A/1 | B7: 07921684700
A8: MC003 - PD-A/1 | B8: 06438455776
A9: FC045 - LD-B/1 | B9: 14770897723
A10: FC017 - LD-C/1 | B10: 15701554708
A11: FC062 - LDEC/2 | B11: 15701554708
A12: FC063 - LD-C/U | B12: 15701554708
A13: FC009e - LD-B/1 | B13: 15701554708
A14: FC062 - LD-B/2 | B14: 81112459715
... A125: FC038 - PN-C/U | B125: 09617569779

Sheet Alan
A1: =IF(C1="ENCAR",CONCATENATE(B1," - ",C1),IF(C1="ZELAD",CONCATENATE(B1," - ",C1),CONCATENATE(B1," - ",(CONCATENATE(MID(C1,1,1),MID(D1,1,1),MID(E1,1,1),MID(F1,1,1),"/",MID(G1,1,1)))))) -> - / | H1: =IF(I1=0,"-",IF(J1=0,CONCATENATE("R",I1),CONCATENATE("R",I1,"/",J1))) -> - | K1: =VLOOKUP(B1,#REF!,2,FALSE()) -> #REF! | L1: =VLOOKUP(B1,#REF!,7,FALSE()) -> #REF! | Q1: =VLOOKUP(B1,#REF!,10,FALSE()) -> #REF!
B3: COD CLIENTE | C3: CATEGORIA DE POSTO | D3: TURNO | E3: CONDI ÇÃO | F3: TIPO ESCALA | G3: QUANT. | H3: ROTEIRO | K3: CONTRATO | L3: LOCALIZAÇÃO | M3: CESTA BASICA | N3: INSALUB / PERICULOSIDADE | O3: NR EXIGIDA | P3: FERIADOS | Q3: supervisor | R3: DESCRIÇÃO DA ESCALA - dia da semana + horario | S3: HORAS DIÁRIAS | T3: seg | V3: ter | X3: qua | Z3: qui | AB3: sex | AD3: sab | AF3: dom | AH3: translado | AI3: ESCALA JAN | AJ3: ESCALA FEV | AK3: ESCALA MAR | AL3: ESCALA ABR | AM3: ESCALA MAI | AN3: ESCALA JUN | AO3: ESCALA JUL | AP3: ESCALA AGO | AQ3: ESCALA SET | AR3: ESCALA OUT | AS3: ESCALA NOV | AT3: ESCALA DEZ | AV3: ESCALA JAN | AW3: ESCALA FEV | AX3: ESCALA MAR | AY3: ESCALA ABR | AZ3: ESCALA MAI | BA3: ESCALA JUN | BB3: ESCALA JUL | BC3: ESCALA AGO | BD3: ESCALA SET | BE3: ESCALA OUT | BF3: ESCALA NOV | BG3: ESCALA DEZ | BI3: 06:00 às 07:00 | BJ3: 07:00 às 08:00 | BK3: 08:00 às 09:00 | BL3: 09:00 às 10:00 | BM3: 11:00 às 12:00 | BN3: 13:00 às 14:00 | BO3: 14:00 às 15:00 | BP3: 19:00 às 07:00 | BQ3: 20:00 às 21:00 | BR3: 22:00 às 23:00
B4: z | H4: =IF(I4=0,"-",IF(J4=0,CONCATENATE("R",I4),CONCATENATE("R",I4,"/",J4))) -> - | K4: Coloque dados na planilha de disponibilidade | Q4: =VLOOKUP(B4,#REF!,14,FALSE()) -> #REF!
B5: z | H5: =IF(I5=0,"-",IF(J5=0,CONCATENATE("R",I5),CONCATENATE("R",I5,"/",J5))) -> - | K5: Indique que faz a cobertura | Q5: =VLOOKUP(B5,#REF!,14,FALSE()) -> #REF!
B6: z | H6: =IF(I6=0,"-",IF(J6=0,CONCATENATE("R",I6),CONCATENATE("R",I6,"/",J6))) -> - | K6: Movimente esse colaborador para a área de atestados | Q6: =VLOOKUP(B6,#REF!,14,FALSE()) -> #REF!
B7: z | H7: =IF(I7=0,"-",IF(J7=0,CONCATENATE("R",I7),CONCATENATE("R",I7,"/",J7))) -> - | K7: Retire esse colaborador da planilha de disponibilidade | Q7: =VLOOKUP(B7,#REF!,14,FALSE()) -> #REF!
B8: z | H8: =IF(I8=0,"-",IF(J8=0,CONCATENATE("R",I8),CONCATENATE("R",I8,"/",J8))) -> - | Q8: =VLOOKUP(B8,#REF!,14,FALSE()) -> #REF!
B9: R01 | H9: =IF(I9=0,"-",IF(J9=0,CONCATENATE("R",I9),CONCATENATE("R",I9,"/",J9))) -> R.01 | I9: .01 | L9: =VLOOKUP(B9,ROTEIRO!$B$1:$AH$201,4,FALSE()) -> #N/A | Q9: =VLOOKUP(B9,#REF!,14,FALSE()) -> #REF!
B10: R02 | H10: =IF(I10=0,"-",IF(J10=0,CONCATENATE("R",I10),CONCATENATE("R",I10,"/",J10))) -> R.02 | I10: .02 | L10: =VLOOKUP(B10,ROTEIRO!$B$2:$AH$201,4,FALSE()) -> #N/A | Q10: =VLOOKUP(B10,#REF!,14,FALSE()) -> #REF!
B11: R03 | H11: =IF(I11=0,"-",IF(J11=0,CONCATENATE("R",I11),CONCATENATE("R",I11,"/",J11))) -> R.03 | I11: .03 | L11: =VLOOKUP(B11,ROTEIRO!$B$2:$AH$201,4,FALSE()) -> R03/1 | Q11: =VLOOKUP(B11,#REF!,14,FALSE()) -> #REF!
B12: R04 | H12: =IF(I12=0,"-",IF(J12=0,CONCATENATE("R",I12),CONCATENATE("R",I12,"/",J12))) -> R.04 | I12: .04 | L12: =VLOOKUP(B12,ROTEIRO!$B$2:$AH$201,4,FALSE()) -> R04/1 | Q12: =VLOOKUP(B12,#REF!,14,FALSE()) -> #REF!
B13: MC002 | C13: PORTEIRO | D13: DIURNO | E13: - | F13: B - 44 horas | G13: UNICO | H13: =IF(I13=0,"-",IF(J13=0,CONCATENATE("R",I13),CONCATENATE("R",I13,"/",J13))) -> - | K13: =VLOOKUP(B13,#REF!,2,FALSE()) -> #REF! | L13: =VLOOKUP(B13,#REF!,7,FALSE()) -> #REF! | M13: Cesta Gd | N13: N/A | O13: N/A | P13: SEM COBERT | Q13: =VLOOKUP(B13,#REF!,10,FALSE()) -> #REF! | R13: Seg à Qui - 08:00 às 18:00 / Sex - 08:00 às 17:00 - Intervalo: 12h - 13h - Pausa: 17h - 17h15 - Folga: Sab e Dom | S13: =U13+W13+Y13+AA13+AC13+AE13+AG13+AH13 -> 1.8333333 | T13: 07:00 às 17:00 | U13: 0.375 | V13: 07:00 às 17:00 | W13: 0.375 | X13: 07:00 às 17:00 | Y13: 0.375 | Z13: 07:00 às 17:00 | AA13: 0.375 | AB13: 07:00 às 16:00 | AC13: 0.33333333 | AD13: FOLGA | AF13: FOLGA
B14: R05 | H14: =IF(I14=0,"-",IF(J14=0,CONCATENATE("R",I14),CONCATENATE("R",I14,"/",J14))) -> R.05 | I14: .05 | L14: =VLOOKUP(B14,ROTEIRO!$B$2:$AH$201,4,FALSE()) -> R05/1 | Q14: =VLOOKUP(B14,#REF!,14,FALSE()) -> #REF!
B15: R06 | H15: =IF(I15=0,"-",IF(J15=0,CONCATENATE("R",I15),CONCATENATE("R",I15,"/",J15))) -> R.06 | I15: .06 | L15: =VLOOKUP(B15,ROTEIRO!$B$2:$AH$201,4,FALSE()) -> R06/1 | Q15: =VLOOKUP(B15,#REF!,14,FALSE()) -> #REF!
B16: R07 | H16: =IF(I16=0,"-",IF(J16=0,CONCATENATE("R",I16),CONCATENATE("R",I16,"/",J16))) -> R.07 | I16: .07 | L16: =VLOOKUP(B16,ROTEIRO!$B$2:$AH$201,4,FALSE()) -> R07/1 | Q16: =VLOOKUP(B16,#REF!,14,FALSE()) -> #REF!
B17: AG007 | C17: LIMPADOR | D17: DIURNO | E17: - | F17: B - 44 horas | G17: UNICO | H17: =IF(I17=0,"-",IF(J17=0,CONCATENATE("R",I17),CONCATENATE("R",I17,"/",J17))) -> - | K17: =VLOOKUP(B17,#REF!,2,FALSE()) -> #REF! | L17: =VLOOKUP(B17,#REF!,7,FALSE()) -> #REF! | M17: Cesta Gd | N17: N/A | O17: N/A | P17: SEM COBERT | Q17: =VLOOKUP(B17,#REF!,10,FALSE()) -> #REF! | R17: Seg à Sex - 08:00 às 16:40 / Sáb - 08:00 às 14:40 - Intervalo: 12h - 13h - Pausa: N/A - Folga: Domingos | S17: =U17+W17+Y17+AA17+AC17+AE17+AG17+AH17 -> 1.8333333 | T17: 08:00 às 16:40 | U17: 0.31944444 | V17: 08:00 às 16:40 | W17: 0.31944444 | X17: 08:00 às 16:40 | Y17: 0.31944444 | Z17: 08:00 às 16:40 | AA17: 0.31944444 | AB17: 08:00 às 16:40 | AC17: 0.31944444 | AD17: 8:00 às 14:40 | AE17: 0.23611111 | AF17: FOLGA
B18: R08 | H18: =IF(I18=0,"-",IF(J18=0,CONCATENATE("R",I18),CONCATENATE("R",I18,"/",J18))) -> R.08 | I18: .08 | L18: =VLOOKUP(B18,ROTEIRO!$B$2:$AH$201,4,FALSE()) -> R08/1 | Q18: =VLOOKUP(B18,#REF!,14,FALSE()) -> #REF!
B19: R09 | H19: =IF(I19=0,"-",IF(J19=0,CONCATENATE("R",I19),CONCATENATE("R",I19,"/",J19))) -> R.09 | I19: .09 | L19: =VLOOKUP(B19,ROTEIRO!$B$2:$AH$201,4,FALSE()) -> R09/1 | Q19: =VLOOKUP(B19,#REF!,14,FALSE()) -> #REF!
B20: R10 | H20: =IF(I20=0,"-",IF(J20=0,CONCATENATE("R",I20),CONCATENATE("R",I20,"/",J20))) -> R.10 | I20: .10 | L20: =VLOOKUP(B20,ROTEIRO!$B$2:$AH$201,4,FALSE()) -> R10/1 | Q20: =VLOOKUP(B20,#REF!,14,FALSE()) -> #REF!
B21: AG062 | C21: ENCAR | H21: =IF(I21=0,"-",IF(J21=0,CONCATENATE("R",I21),CONCATENATE("R",I21,"/",J21))) -> - | K21: =VLOOKUP(B21,#REF!,2,FALSE()) -> #REF! | L21: =VLOOKUP(B21,#REF!,7,FALSE()) -> #REF! | M21: Cesta Gd | N21: N/A | O21: N/A | P21: COB MISTA | Q21: =VLOOKUP(B21,#REF!,10,FALSE()) -> #REF! | R21: Seg à Dom - 08:00 às 16:20 - Intervalo: 12h - 13h - Pausa: N/A - Folga: Sextas + 4º DOM | S21: 1.8333333 | T21: 08:00 às 16:20 | U21: 0.30555556 | V21: 08:00 às 16:20 | W21: 0.30555556 | X21: 08:00 às 16:20 | Y21: 0.30555556 | Z21: 08:00 às 16:20 | AA21: 0.30555556 | AB21: FOLGA | AD21: 08:00 às 16:20 | AE21: 0.30555556 | AF21: 08:00 às 16:20 | AG21: 0.30555556
B22: R11 | H22: =IF(I22=0,"-",IF(J22=0,CONCATENATE("R",I22),CONCATENATE("R",I22,"/",J22))) -> R.11 | I22: .11 | L22: =VLOOKUP(B22,ROTEIRO!$B$2:$AH$201,4,FALSE()) -> R11/1 | Q22: =VLOOKUP(B22,#REF!,14,FALSE()) -> #REF!
B23: R12 | H23: =IF(I23=0,"-",IF(J23=0,CONCATENATE("R",I23),CONCATENATE("R",I23,"/",J23))) -> R.12 | I23: .12 | L23: =VLOOKUP(B23,ROTEIRO!$B$2:$AH$201,4,FALSE()) -> R12/1 | Q23: =VLOOKUP(B23,#REF!,14,FALSE()) -> #REF!
B24: FC001a | C24: LIMPADOR | D24: DIURNO | E24: - | F24: B - 44 horas | G24: UNICO | H24: =IF(I24=0,"-",IF(J24=0,CONCATENATE("R",I24),CONCATENATE("R",I24,"/",J24))) -> - | K24: =VLOOKUP(B24,#REF!,2,FALSE()) -> #REF! | L24: =VLOOKUP(B24,#REF!,7,FALSE()) -> #REF! | M24: Cesta Gd | N24: N/A | O24: N/A | P24: SEM COBERT | Q24: =VLOOKUP(B24,#REF!,10,FALSE()) -> #REF! | R24: Seg à Sex - 07:12 às 17:00 - Intervalo: 11:30h - 12:30 - Pausa: N/A - Folga: Sáb e Dom | S24: 1.8333333 | T24: 07:12 às 17:00 | U24: 0.325 | V24: 07:12 às 17:00 | W24: 0.325 | X24: 07:12 às 17:00 | Y24: 0.325 | Z24: 07:12 às 17:00 | AA24: 0.325 | AB24: 07:12 às 17:00 | AC24: 0.325 | AD24: FOLGA | AF24: FOLGA
B25: FC001b | C25: LIMPADOR | D25: DIURNO | E25: - | F25: B - 44 horas | G25: UNICO | H25: =IF(I25=0,"-",IF(J25=0,CONCATENATE("R",I25),CONCATENATE("R",I25,"/",J25))) -> - | K25: =VLOOKUP(B25,#REF!,2,FALSE()) -> #REF! | L25: =VLOOKUP(B25,#REF!,7,FALSE()) -> #REF! | M25: Cesta Gd | N25: N/A | O25: N/A | P25: SEM COBERT | Q25: =VLOOKUP(B25,#REF!,10,FALSE()) -> #REF! | R25: Seg à Sex - 07:12 às 17:00 - Intervalo: 11:30h - 12:30 - Pausa: N/A - Folga: Sáb e Dom | S25: 1.8333333 | T25: 07:12 às 17:00 | U25: 0.325 | V25: 07:12 às 17:00 | W25: 0.325 | X25: 07:12 às 17:00 | Y25: 0.325 | Z25: 07:12 às 17:00 | AA25: 0.325 | AB25: 07:12 às 17:00 | AC25: 0.325 | AD25: FOLGA | AF25: FOLGA
B26: R13 | H26: =IF(I26=0,"-",IF(J26=0,CONCATENATE("R",I26),CONCATENATE("R",I26,"/",J26))) -> R.13 | I26: .13 | L26: =VLOOKUP(B26,ROTEIRO!$B$2:$AH$201,4,FALSE()) -> R13/1 | Q26: =VLOOKUP(B26,#REF!,14,FALSE()) -> #REF!
B27: R14 | H27: =IF(I27=0,"-",IF(J27=0,CONCATENATE("R",I27),CONCATENATE("R",I27,"/",J27))) -> R.14 | I27: .14 | L27: =VLOOKUP(B27,ROTEIRO!$B$2:$AH$201,4,FALSE()) -> R14/1 | Q27: =VLOOKUP(B27,#REF!,14,FALSE()) -> #REF!
B28: R15 | H28: =IF(I28=0,"-",IF(J28=0,CONCATENATE("R",I28),CONCATENATE("R",I28,"/",J28))) -> R.15 | I28: .15 | L28: =VLOOKUP(B28,ROTEIRO!$B$2:$AH$201,4,FALSE()) -> R15/1 | Q28: =VLOOKUP(B28,#REF!,14,FALSE()) -> #REF!
B29: AG065 | C29: LIMPADOR | D29: DIURNO | E29: - | F29: B - 44 horas | G29: UNICO | H29: =IF(I29=0,"-",IF(J29=0,CONCATENATE("R",I29),CONCATENATE("R",I29,"/",J29))) -> - | K29: =VLOOKUP(B29,#REF!,2,FALSE()) -> #REF! | L29: =VLOOKUP(B29,#REF!,7,FALSE()) -> #REF! | Q29: =VLOOKUP(B29,#REF!,10,FALSE()) -> #REF! | R29: Seg à Sáb - 08:20 às 16:40 - intervalo: 13h - 14h - Pausa: N/A - Folga: Domingo | S29: 1.8333333 | T29: 08:20 às 16:40 | U29: 0.30555556 | V29: 08:20 às 16:40 | W29: 0.30555556 | X29: 08:20 às 16:40 | Y29: 0.30555556 | Z29: 08:20 às 16:40 | AA29: 0.30555556 | AB29: 08:20 às 16:40 | AC29: 0.30555556 | AD29: 08:20 às 16:40 | AE29: 0.30555556
B30: R16 | H30: =IF(I30=0,"-",IF(J30=0,CONCATENATE("R",I30),CONCATENATE("R",I30,"/",J30))) -> R.16 | I30: .16 | L30: =VLOOKUP(B30,ROTEIRO!$B$2:$AH$201,4,FALSE()) -> R16/1 | Q30: =VLOOKUP(B30,#REF!,14,FALSE()) -> #REF!
B31: R17 | H31: =IF(I31=0,"-",IF(J31=0,CONCATENATE("R",I31),CONCATENATE("R",I31,"/",J31))) -> R.17 | I31: .17 | L31: =VLOOKUP(B31,ROTEIRO!$B$2:$AH$201,4,FALSE()) -> 0 | Q31: =VLOOKUP(B31,#REF!,14,FALSE()) -> #REF!
B32: R18 | H32: =IF(I32=0,"-",IF(J32=0,CONCATENATE("R",I32),CONCATENATE("R",I32,"/",J32))) -> R.18 | I32: .18 | L32: =VLOOKUP(B32,ROTEIRO!$B$2:$AH$201,4,FALSE()) | Q32: =VLOOKUP(B32,#REF!,14,FALSE()) -> #REF!
B33: R19 | H33: =IF(I33=0,"-",IF(J33=0,CONCATENATE("R",I33),CONCATENATE("R",I33,"/",J33))) -> R.19 | I33: .19 | L33: =VLOOKUP(B33,ROTEIRO!$B$2:$AH$201,4,FALSE()) | Q33: =VLOOKUP(B33,#REF!,14,FALSE()) -> #REF!
B34: R20 | H34: =IF(I34=0,"-",IF(J34=0,CONCATENATE("R",I34),CONCATENATE("R",I34,"/",J34))) -> R.20 | I34: .20 | L34: =VLOOKUP(B34,ROTEIRO!$B$2:$AH$201,4,FALSE()) | Q34: =VLOOKUP(B34,#REF!,14,FALSE()) -> #REF!
K35: =COUNTIF(K24:K107,"<>0") -> 48
A36: =IF(C36="ENCAR",CONCATENATE(B36," - ",C36),IF(C36="ZELAD",CONCATENATE(B36," - ",C36),CONCATENATE(B36," - ",(CONCATENATE(MID(C36,1,1),MID(D36,1,1),MID(E36,1,1),MID(F36,1,1),"/",MID(G36,1,1)))))) -> AG023 - JD-B/U | B36: AG023 | C36: JARDINEIRO | D36: DIURNO | E36: - | F36: B - 44 horas | G36: UNICO | H36: =IF(I36=0,"-",IF(J36=0,CONCATENATE("R",I36),CONCATENATE("R",I36,"/",J36))) -> - | K36: =VLOOKUP(B36,#REF!,2,FALSE()) -> #REF! | L36: =VLOOKUP(B36,#REF!,7,FALSE()) -> #REF! | M36: Cesta Gd | N36: N/A | O36: N/A | P36: SEM COBERT | Q36: =VLOOKUP(B36,#REF!,10,FALSE()) -> #REF! | R36: Seg à Sex - 06:00 às 15:00 / Sáb - 06:00 às 10:00 - Intervalo: 12h - 13h - Pausa: N/A - Folga: Domingos | S36: 1.8333333 | T36: 06:00 às 15:00 | U36: 0.33333333 | V36: 06:00 às 15:00 | W36: 0.33333333 | X36: 06:00 às 15:00 | Y36: 0.33333333 | Z36: 06:00 às 15:00 | AA36: 0.33333333 | AB36: 06:00 às 15:00 | AC36: 0.33333333 | AD36: 06:00 às 10:00 | AE36: 0.16666667 | AF36: FOLGA | BI36: X
A37: =IF(C37="ENCAR",CONCATENATE(B37," - ",C37),IF(C37="ZELAD",CONCATENATE(B37," - ",C37),CONCATENATE(B37," - ",(CONCATENATE(MID(C37,1,1),MID(D37,1,1),MID(E37,1,1),MID(F37,1,1),"/",MID(G37,1,1)))))) -> FC066 - MD-B/U | B37: FC066 | C37: MANUTENCIONISTA | D37: DIURNO | E37: - | F37: B - 44 horas | G37: UNICO | H37: =IF(I37=0,"-",IF(J37=0,CONCATENATE("R",I37),CONCATENATE("R",I37,"/",J37))) -> - | K37: =VLOOKUP(B37,#REF!,2,FALSE()) -> #REF! | L37: =VLOOKUP(B37,#REF!,7,FALSE()) -> #REF! | M37: Cesta Gd | N37: N/A | O37: N/A | P37: SEM COBERT | Q37: =VLOOKUP(B37,#REF!,10,FALSE()) -> #REF! | R37: Seg à Sex - 07:00 às 16:00 / Sáb - 07:00 às 11:00 - Intervalo: 11h - 12h - Pausa: N/A - Folga: Dom e Fer | S37: =U37+W37+Y37+AA37+AC37+AE37+AG37+AH37 -> 1.8333333 | T37: 07:00 às 16:00 | U37: 0.33333333 | V37: 07:00 às 16:00 | W37: 0.33333333 | X37: 07:00 às 16:00 | Y37: 0.33333333 | Z37: 07:00 às 16:00 | AA37: 0.33333333 | AB37: 07:00 às 16:00 | AC37: 0.33333333 | AD37: 07:00 às 11:00 | AE37: 0.16666667 | AF37: FOLGA | BI37: X
A38: =IF(C38="ENCAR",CONCATENATE(B38," - ",C38),IF(C38="ZELAD",CONCATENATE(B38," - ",C38),CONCATENATE(B38," - ",(CONCATENATE(MID(C38,1,1),MID(D38,1,1),MID(E38,1,1),MID(F38,1,1),"/",MID(G38,1,1)))))) -> AG005 - PD-A/1 | B38: AG005 | C38: PORTEIRO | D38: DIURNO | E38: - | F38: A - 12 por 36 | G38: 1 | H38: =IF(I38=0,"-",IF(J38=0,CONCATENATE("R",I38),CONCATENATE("R",I38,"/",J38))) -> - | K38: =VLOOKUP(B38,#REF!,2,FALSE()) -> #REF! | L38: =VLOOKUP(B38,#REF!,7,FALSE()) -> #REF! | M38: Cesta Gd | N38: N/A | O38: N/A | P38: COB ESCALA | Q38: =VLOOKUP(B38,#REF!,10,FALSE()) -> #REF! | R38: 12 por 36 - 07:00 às 19:00 - Intervalo: Pago aos dom. e feriados - Pausa: 16h - 16h15 - Folga: N/A | S38: 1.8333333 | T38: 07:00 às 19:00 | U38: 0.5 | X38: 07:00 às 19:00 | Y38: 0.5 | AB38: 07:00 às 19:00 | AC38: 0.5 | AF38: 07:00 às 19:00 | AG38: 0.5 | AI38: ESCALA PAR | AJ38: ESCALA IMPAR | AK38: ESCALA IMPAR | AL38: ESCALA PAR | AM38: ESCALA IMPAR | AN38: ESCALA IMPAR | AO38: ESCALA PAR | AP38: ESCALA PAR | AQ38: ESCALA IMPAR | AR38: ESCALA PAR | AS38: ESCALA IMPAR | AT38: ESCALA PAR | BI38: X
A39: =IF(C39="ENCAR",CONCATENATE(B39," - ",C39),IF(C39="ZELAD",CONCATENATE(B39," - ",C39),CONCATENATE(B39," - ",(CONCATENATE(MID(C39,1,1),MID(D39,1,1),MID(E39,1,1),MID(F39,1,1),"/",MID(G39,1,1)))))) -> AG005 - PD-A/2 | B39: AG005 | C39: PORTEIRO | D39: DIURNO | E39: - | F39: A - 12 por 36 | G39: 2 | H39: =IF(I39=0,"-",IF(J39=0,CONCATENATE("R",I39),CONCATENATE("R",I39,"/",J39))) -> - | K39: =VLOOKUP(B39,#REF!,2,FALSE()) -> #REF! | L39: =VLOOKUP(B39,#REF!,7,FALSE()) -> #REF! | M39: Cesta Gd | N39: N/A | O39: N/A | P39: COB ESCALA | Q39: =VLOOKUP(B39,#REF!,10,FALSE()) -> #REF! | R39: 12 por 36 - 07:00 às 19:00 - Intervalo: Pago aos dom. e feriados - Pausa: 16h - 16h15 - Folga: N/A | S39: 1.8333333 | V39: 07:00 às 19:00 | W39: 0.5 | Z39: 07:00 às 19:00 | AA39: 0.5 | AD39: 07:00 às 19:00 | AE39: 0.5 | AI39: ESCALA IMPAR | AJ39: ESCALA PAR | AK39: ESCALA PAR | AL39: ESCALA IMPAR | AM39: ESCALA PAR | AN39: ESCALA PAR | AO39: ESCALA IMPAR | AP39: ESCALA IMPAR | AQ39: ESCALA PAR | AR39: ESCALA IMPAR | AS39: ESCALA PAR | AT39: ESCALA IMPAR | BI39: X
A40: =IF(C40="ENCAR",CONCATENATE(B40," - ",C40),IF(C40="ZELAD",CONCATENATE(B40," - ",C40),CONCATENATE(B40," - ",(CONCATENATE(MID(C40,1,1),MID(D40,1,1),MID(E40,1,1),MID(F40,1,1),"/",MID(G40,1,1)))))) -> FC067 - LD-B/U | B40: FC067 | C40: LIMPADOR | D40: DIURNO | E40: - | F40: B - 44 horas | G40: UNICO | H40: =IF(I40=0,"-",IF(J40=0,CONCATENATE("R",I40),CONCATENATE("R",I40,"/",J40))) -> - | K40: =VLOOKUP(B40,#REF!,2,FALSE()) -> #REF! | L40: =VLOOKUP(B40,#REF!,7,FALSE()) -> #REF! | M40: Cesta Gd | N40: N/A | O40: N/A | P40: SEM COBERT | Q40: =VLOOKUP(B40,#REF!,10,FALSE()) -> #REF! | R40: Seg à Sex - 07:20 às 16:20/ Sáb - 07:20 às 11:20 - Intervalo: 12h - 13h - Pausa: N/A - Folga: Dom e Fer | S40: 1.8333333 | T40: 08:00 às 17:00 | U40: 0.33333333 | V40: 08:00 às 17:00 | W40: 0.33333333 | X40: 08:00 às 17:00 | Y40: 0.33333333 | Z40: 08:00 às 17:00 | AA40: 0.33333333 | AB40: 08:00 às 17:00 | AC40: 0.33333333 | AD40: 08:00 às 12:00 | AE40: 0.16666667 | AF40: FOLGA | BJ40: X
A41: =IF(C41="ENCAR",CONCATENATE(B41," - ",C41),IF(C41="ZELAD",CONCATENATE(B41," - ",C41),CONCATENATE(B41," - ",(CONCATENATE(MID(C41,1,1),MID(D41,1,1),MID(E41,1,1),MID(F41,1,1),"/",MID(G41,1,1)))))) -> AG017 - LD-C/U | B41: AG017 | C41: LIMPADOR | D41: DIURNO | E41: - | F41: C - menos de 44h | G41: UNICO | H41: =IF(I41=0,"-",IF(J41=0,CONCATENATE("R",I41),CONCATENATE("R",I41,"/",J41))) -> Reduzido | I41: eduzido | K41: =VLOOKUP(B41,#REF!,2,FALSE()) -> #REF! | L41: =VLOOKUP(B41,#REF!,7,FALSE()) -> #REF! | M41: Roteiro ou Contagem | N41: N/A | O41: N/A | P41: SEM COBERT | Q41: =VLOOKUP(B41,#REF!,10,FALSE()) -> #REF! | R41: Seg à Sáb - 07:30 às 11:30 - Intervalo: N/A - Pausa: N/A - Folga: N/A | S41: =U41+W41+Y41+AA41+AC41+AE41+AG41+AH41 -> 1 | T41: 07:30 às 11:30 | U41: 0.16666667 | V41: 07:30 às 11:30 | W41: 0.16666667 | X41: 07:30 às 11:30 | Y41: 0.16666667 | Z41: 07:30 às 11:30 | AA41: 0.16666667 | AB41: 07:30 às 11:30 | AC41: 0.16666667 | AD41: 07:30 às 11:30 | AE41: 0.16666667 | AF41: FOLGA | AV41: ESCALA PAR | AW41: ESCALA IMPAR | AX41: ESCALA IMPAR | AY41: ESCALA PAR | AZ41: ESCALA IMPAR | BA41: ESCALA IMPAR | BB41: ESCALA PAR | BC41: ESCALA PAR | BD41: ESCALA IMPAR | BE41: ESCALA PAR | BF41: ESCALA IMPAR | BG41: ESCALA PAR | BJ41: X
...

Sheet Bernardo
A1: =IF(C1="ENCAR",CONCATENATE(B1," - ",C1),IF(C1="ZELAD",CONCATENATE(B1," - ",C1),CONCATENATE(B1," - ",(CONCATENATE(MID(C1,1,1),MID(D1,1,1),MID(E1,1,1),MID(F1,1,1),"/",MID(G1,1,1)))))) -> - / | H1: =IF(I1=0,"-",IF(J1=0,CONCATENATE("R",I1),CONCATENATE("R",I1,"/",J1))) -> - | K1: =VLOOKUP(B1,#REF!,2,FALSE()) -> #REF! | L1: =VLOOKUP(B1,#REF!,7,FALSE()) -> #REF! | Q1: =VLOOKUP(B1,#REF!,10,FALSE()) -> #REF!
B3: COD CLIENTE | C3: CATEGORIA DE POSTO | D3: TURNO | E3: CONDI ÇÃO | F3: TIPO ESCALA | G3: QUANT. | H3: ROTEIRO | K3: CONTRATO | L3: LOCALIZAÇÃO | M3: CESTA BASICA | N3: INSALUB / PERICULOSIDADE | O3: NR EXIGIDA | P3: FERIADOS | Q3: supervisor | R3: DESCRIÇÃO DA ESCALA - dia da semana + horario | S3: HORAS DIÁRIAS | T3: seg | V3: ter | X3: qua | Z3: qui | AB3: sex | AD3: sab | AF3: dom | AH3: translado | AI3: ESCALA JAN | AJ3: ESCALA FEV | AK3: ESCALA MAR | AL3: ESCALA ABR | AM3: ESCALA MAI | AN3: ESCALA JUN | AO3: ESCALA JUL | AP3: ESCALA AGO | AQ3: ESCALA SET | AR3: ESCALA OUT | AS3: ESCALA NOV | AT3: ESCALA DEZ | AV3: ESCALA JAN | AW3: ESCALA FEV | AX3: ESCALA MAR | AY3: ESCALA ABR | AZ3: ESCALA MAI | BA3: ESCALA JUN | BB3: ESCALA JUL | BC3: ESCALA AGO | BD3: ESCALA SET | BE3: ESCALA OUT | BF3: ESCALA NOV | BG3: ESCALA DEZ | BJ3: 06:00 às 07:00 | BK3: 07:00 às 08:00 | BL3: 08:00 às 09:00 | BM3: 09:00 às 10:00 | BN3: 11:00 às 12:00 | BO3: 12:00 às 13:00 | BP3: 13:00 às 14:00 | BQ3: 14:00 às 15:00 | BR3: 18:00 às 19:00 | BS3: 19:00 às 20:00 | BT3: 20:00 às 21:00 | BU3: 21:00 às 22:00
B4: z | H4: =IF(I4=0,"-",IF(J4=0,CONCATENATE("R",I4),CONCATENATE("R",I4,"/",J4))) -> - | K4: Coloque dados na planilha de disponibilidade | Q4: =VLOOKUP(B4,#REF!,14,FALSE()) -> #REF!
B5: z | H5: =IF(I5=0,"-",IF(J5=0,CONCATENATE("R",I5),CONCATENATE("R",I5,"/",J5))) -> - | K5: Indique que faz a cobertura | Q5: =VLOOKUP(B5,#REF!,14,FALSE()) -> #REF!
B6: z | H6: =IF(I6=0,"-",IF(J6=0,CONCATENATE("R",I6),CONCATENATE("R",I6,"/",J6))) -> - | K6: Movimente esse colaborador para a área de atestados | Q6: =VLOOKUP(B6,#REF!,14,FALSE()) -> #REF!
B7: z | H7: =IF(I7=0,"-",IF(J7=0,CONCATENATE("R",I7),CONCATENATE("R",I7,"/",J7))) -> - | K7: Retire esse colaborador da planilha de disponibilidade | Q7: =VLOOKUP(B7,#REF!,14,FALSE()) -> #REF!
B8: z | H8: =IF(I8=0,"-",IF(J8=0,CONCATENATE("R",I8),CONCATENATE("R",I8,"/",J8))) -> - | Q8: =VLOOKUP(B8,#REF!,14,FALSE()) -> #REF!
B9: R01 | H9: =IF(I9=0,"-",IF(J9=0,CONCATENATE("R",I9),CONCATENATE("R",I9,"/",J9))) -> R.01 | I9: .01 | L9: =VLOOKUP(B9,ROTEIRO!$B$1:$AH$201,4,FALSE()) -> #N/A | Q9: =VLOOKUP(B9,#REF!,14,FALSE()) -> #REF!
B10: R02 | H10: =IF(I10=0,"-",IF(J10=0,CONCATENATE("R",I10),CONCATENATE("R",I10,"/",J10))) -> R.02 | I10: .02 | L10: =VLOOKUP(B10,ROTEIRO!$B$2:$AH$201,4,FALSE()) -> #N/A | Q10: =VLOOKUP(B10,#REF!,14,FALSE()) -> #REF!
B11: R03 | H11: =IF(I11=0,"-",IF(J11=0,CONCATENATE("R",I11),CONCATENATE("R",I11,"/",J11))) -> R.03 | I11: .03 | L11: =VLOOKUP(B11,ROTEIRO!$B$2:$AH$201,4,FALSE()) -> R03/1 | Q11: =VLOOKUP(B11,#REF!,14,FALSE()) -> #REF!
B12: R04 | H12: =IF(I12=0,"-",IF(J12=0,CONCATENATE("R",I12),CONCATENATE("R",I12,"/",J12))) -> R.04 | I12: .04 | L12: =VLOOKUP(B12,ROTEIRO!$B$2:$AH$201,4,FALSE()) -> R04/1 | Q12: =VLOOKUP(B12,#REF!,14,FALSE()) -> #REF!
